<?xml version="1.0" encoding="UTF-8"?>
<testng-results skipped="0" failed="1" total="1" passed="0">
  <reporter-output>
  </reporter-output>
  <suite name="Suite" duration-ms="20027" started-at="2016-04-19T17:35:57Z" finished-at="2016-04-19T17:36:17Z">
    <groups>
    </groups>
    <test name="Test" duration-ms="20027" started-at="2016-04-19T17:35:57Z" finished-at="2016-04-19T17:36:17Z">
      <class name="OpenSource.Selenium.TestInitiate">
        <test-method status="FAIL" signature="TestInitiate_method()" name="TestInitiate_method" duration-ms="19963" started-at="2016-04-19T17:35:57Z" finished-at="2016-04-19T17:36:17Z">
          <exception class="java.lang.reflect.InvocationTargetException">
            <full-stacktrace>
              <![CDATA[java.lang.reflect.InvocationTargetException
	at sun.reflect.NativeMethodAccessorImpl.invoke0(Native Method)
	at sun.reflect.NativeMethodAccessorImpl.invoke(NativeMethodAccessorImpl.java:57)
	at sun.reflect.DelegatingMethodAccessorImpl.invoke(DelegatingMethodAccessorImpl.java:43)
	at java.lang.reflect.Method.invoke(Method.java:606)
	at OpenSource.Selenium.ReflectionClass.callMethods(ReflectionClass.java:53)
	at OpenSource.Selenium.TestInitiate.TestInitiate_method(TestInitiate.java:43)
	at sun.reflect.NativeMethodAccessorImpl.invoke0(Native Method)
	at sun.reflect.NativeMethodAccessorImpl.invoke(NativeMethodAccessorImpl.java:57)
	at sun.reflect.DelegatingMethodAccessorImpl.invoke(DelegatingMethodAccessorImpl.java:43)
	at java.lang.reflect.Method.invoke(Method.java:606)
	at org.testng.internal.MethodInvocationHelper.invokeMethod(MethodInvocationHelper.java:80)
	at org.testng.internal.Invoker.invokeMethod(Invoker.java:673)
	at org.testng.internal.Invoker.invokeTestMethod(Invoker.java:842)
	at org.testng.internal.Invoker.invokeTestMethods(Invoker.java:1166)
	at org.testng.internal.TestMethodWorker.invokeTestMethods(TestMethodWorker.java:125)
	at org.testng.internal.TestMethodWorker.run(TestMethodWorker.java:109)
	at org.testng.TestRunner.runWorkers(TestRunner.java:1178)
	at org.testng.TestRunner.privateRun(TestRunner.java:757)
	at org.testng.TestRunner.run(TestRunner.java:608)
	at org.testng.SuiteRunner.runTest(SuiteRunner.java:334)
	at org.testng.SuiteRunner.runSequentially(SuiteRunner.java:329)
	at org.testng.SuiteRunner.privateRun(SuiteRunner.java:291)
	at org.testng.SuiteRunner.run(SuiteRunner.java:240)
	at org.testng.SuiteRunnerWorker.runSuite(SuiteRunnerWorker.java:52)
	at org.testng.SuiteRunnerWorker.run(SuiteRunnerWorker.java:86)
	at org.testng.TestNG.runSuitesSequentially(TestNG.java:1158)
	at org.testng.TestNG.runSuitesLocally(TestNG.java:1083)
	at org.testng.TestNG.run(TestNG.java:999)
	at org.testng.remote.RemoteTestNG.run(RemoteTestNG.java:111)
	at org.testng.remote.RemoteTestNG.initAndRun(RemoteTestNG.java:203)
	at org.testng.remote.RemoteTestNG.main(RemoteTestNG.java:174)
Caused by: java.lang.AssertionError: expected:<Verify Your Identity | Salesforce> but was:<Find a Flight: Mercury Tours:>
	at org.testng.Assert.fail(Assert.java:89)
	at org.testng.Assert.failNotEquals(Assert.java:489)
	at org.testng.Assert.assertEquals(Assert.java:118)
	at org.testng.Assert.assertEquals(Assert.java:171)
	at org.testng.Assert.assertEquals(Assert.java:181)
	at OpenSource.Selenium.ReflectionClass.verifyLogIn(ReflectionClass.java:130)
	... 31 more
]]>
            </full-stacktrace>
          </exception>
        </test-method>
      </class>
    </test>
  </suite>
</testng-results>
